Workbook

Sheet Orders
A1: Order ID | B1: Order Date | C1: Customer Name | D1: City | E1: State | F1: Channel | G1: Customer Tier | H1: Product Name | I1: Category | J1: Quantity | K1: Unit Price (₹) | L1: Total Revenue (₹) | M1: Status | N1: Is Returned | O1: Rating
A2: ORD-10002 | B2: 45619 | C2: Sneha Sharma | D2: Hyderabad | E2: Telangana | F2: App | G2: Silver | H2: Yoga Mat | I2: Sports | J2: 1 | K2: 1200 | L2: =J2*K2 -> 1200 | M2: Delivered | N2: No | O2: 3
A3: ORD-10003 | B3: 45307 | C3: Amit Singh | D3: Chennai | E3: Tamil Nadu | F3: WhatsApp | G3: Bronze | H3: Wireless Headphones | I3: Electronics | J3: 5 | K3: 3500 | L3: =J3*K3 -> 17500 | M3: Cancelled | N3: No
A4: ORD-10004 | B4: 45571 | C4: Pooja Singh | D4: Ahmedabad | E4: Gujarat | F4: WhatsApp | G4: Silver | H4: Air Purifier | I4: Appliances | J4: 1 | K4: 8700 | L4: =J4*K4 -> 8700 | M4: Returned | N4: Yes
A5: ORD-10005 | B5: 45373 | C5: Pooja Nair | D5: Hyderabad | E5: Telangana | F5: App | G5: Silver | H5: Air Purifier | I5: Appliances | J5: 3 | K5: 4500 | L5: =J5*K5 -> 13500 | M5: Delivered | N5: No | O5: 4
A6: ORD-10006 | B6: 45468 | C6: Deepa Reddy | D6: Mumbai | E6: Maharashtra | F6: Website | G6: Bronze | H6: Running Shoes | I6: Footwear | J6: 4 | K6: 1600 | L6: =J6*K6 -> 6400 | M6: Processing | N6: No
A7: ORD-10007 | B7: 45613 | C7: Deepa Nair | D7: Chennai | E7: Tamil Nadu | F7: App | G7: Gold | H7: Protein Powder | I7: Health | J7: 2 | K7: 1700 | L7: =J7*K7 -> 3400 | M7: Delivered | N7: No | O7: 3
A8: ORD-10008 | B8: 45486 | C8: Arjun Gupta | D8: Pune | E8: Maharashtra | F8: App | G8: Silver | H8: Smartwatch | I8: Electronics | J8: 2 | K8: 8300 | L8: =J8*K8 -> 16600 | M8: Cancelled | N8: No
A9: ORD-10009 | B9: 45623 | C9: Amit Iyer | D9: Bangalore | E9: Karnataka | F9: WhatsApp | G9: Bronze | H9: Coffee Maker | I9: Appliances | J9: 2 | K9: 4800 | L9: =J9*K9 -> 9600 | M9: Shipped | N9: No
A10: ORD-10010 | B10: 45619 | C10: Kavya Singh | D10: Pune | E10: Maharashtra | F10: App | G10: Silver | H10: Sneakers | I10: Footwear | J10: 1 | K10: 4400 | L10: =J10*K10 -> 4400 | M10: Delivered | N10: No | O10: 3
A11: ORD-10011 | B11: 45400 | C11: Sanjay Nair | D11: Chennai | E11: Tamil Nadu | F11: Website | G11: Bronze | H11: Face Cream | I11: Beauty | J11: 4 | K11: 800 | L11: =J11*K11 -> 3200 | M11: Delivered | N11: No | O11: 5
A12: ORD-10012 | B12: 45579 | C12: Kavya Reddy | D12: Kolkata | E12: West Bengal | F12: WhatsApp | G12: Bronze | H12: Smartwatch | I12: Electronics | J12: 2 | K12: 6600 | L12: =J12*K12 -> 13200 | M12: Processing | N12: No
A13: ORD-10013 | B13: 45316 | C13: Sneha Kumar | D13: Bangalore | E13: Karnataka | F13: Website | G13: Bronze | H13: Running Shoes | I13: Footwear | J13: 4 | K13: 2600 | L13: =J13*K13 -> 10400 | M13: Processing | N13: No
A14: ORD-10014 | B14: 45562 | C14: Arjun Mehta | D14: Mumbai | E14: Maharashtra | F14: App | G14: Bronze | H14: Face Cream | I14: Beauty | J14: 5 | K14: 1200 | L14: =J14*K14 -> 6000 | M14: Returned | N14: Yes
A15: ORD-10015 | B15: 45620 | C15: Suresh Patel | D15: Hyderabad | E15: Telangana | F15: Website | G15: Silver | H15: Bluetooth Speaker | I15: Electronics | J15: 1 | K15: 3700 | L15: =J15*K15 -> 3700 | M15: Cancelled | N15: No
A16: ORD-10016 | B16: 45548 | C16: Anjali Mehta | D16: Delhi | E16: Delhi | F16: Website | G16: Bronze | H16: Desk Lamp | I16: Home Decor | J16: 5 | K16: 800 | L16: =J16*K16 -> 4000 | M16: Delivered | N16: No | O16: 3
A17: ORD-10017 | B17: 45568 | C17: Nikhil Sharma | D17: Pune | E17: Maharashtra | F17: Website | G17: Gold | H17: Running Shoes | I17: Footwear | J17: 3 | K17: 2300 | L17: =J17*K17 -> 6900 | M17: Delivered | N17: No | O17: 5
A18: ORD-10018 | B18: 45332 | C18: Amit Gupta | D18: Delhi | E18: Delhi | F18: WhatsApp | G18: Silver | H18: Yoga Mat | I18: Sports | J18: 4 | K18: 1200 | L18: =J18*K18 -> 4800 | M18: Delivered | N18: No | O18: 5
A19: ORD-10019 | B19: 45508 | C19: Kiran Mehta | D19: Chennai | E19: Tamil Nadu | F19: Website | G19: Bronze | H19: Protein Powder | I19: Health | J19: 3 | K19: 2200 | L19: =J19*K19 -> 6600 | M19: Processing | N19: No
A20: ORD-10020 | B20: 45418 | C20: Neha Patel | D20: Pune | E20: Maharashtra | F20: App | G20: Bronze | H20: Desk Lamp | I20: Home Decor | J20: 2 | K20: 1400 | L20: =J20*K20 -> 2800 | M20: Delivered | N20: Yes | O20: 5
A21: ORD-10021 | B21: 45615 | C21: Priya Singh | D21: Delhi | E21: Delhi | F21: App | G21: Silver | H21: Running Shoes | I21: Footwear | J21: 5 | K21: 2100 | L21: =J21*K21 -> 10500 | M21: Delivered | N21: No | O21: 3
A22: ORD-10022 | B22: 45568 | C22: Vikram Iyer | D22: Ahmedabad | E22: Gujarat | F22: App | G22: Bronze | H22: Air Purifier | I22: Appliances | J22: 4 | K22: 5100 | L22: =J22*K22 -> 20400 | M22: Delivered | N22: No | O22: 4
A23: ORD-10023 | B23: 45473 | C23: Pooja Joshi | D23: Ahmedabad | E23: Gujarat | F23: App | G23: Bronze | H23: Protein Powder | I23: Health | J23: 1 | K23: 900 | L23: =J23*K23 -> 900 | M23: Shipped | N23: No
A24: ORD-10024 | B24: 45347 | C24: Neha Singh | D24: Chennai | E24: Tamil Nadu | F24: WhatsApp | G24: Bronze | H24: Yoga Mat | I24: Sports | J24: 4 | K24: 600 | L24: =J24*K24 -> 2400 | M24: Delivered | N24: No | O24: 3
A25: ORD-10025 | B25: 45518 | C25: Kavya Patel | D25: Mumbai | E25: Maharashtra | F25: WhatsApp | G25: Gold | H25: Running Shoes | I25: Footwear | J25: 2 | K25: 1900 | L25: =J25*K25 -> 3800 | M25: Shipped | N25: No
A26: ORD-10026 | B26: 45401 | C26: Ravi Sharma | D26: Bangalore | E26: Karnataka | F26: Website | G26: Gold | H26: Water Bottle | I26: Sports | J26: 3 | K26: 800 | L26: =J26*K26 -> 2400 | M26: Returned | N26: Yes
A27: ORD-10027 | B27: 45524 | C27: Divya Joshi | D27: Ahmedabad | E27: Gujarat | F27: App | G27: Silver | H27: Backpack | I27: Accessories | J27: 2 | K27: 800 | L27: =J27*K27 -> 1600 | M27: Processing | N27: No
A28: ORD-10028 | B28: 45323 | C28: Suresh Sharma | D28: Mumbai | E28: Maharashtra | F28: WhatsApp | G28: Bronze | H28: Desk Lamp | I28: Home Decor | J28: 5 | K28: 700 | L28: =J28*K28 -> 3500 | M28: Delivered | N28: No | O28: 3
A29: ORD-10029 | B29: 45387 | C29: Amit Iyer | D29: Delhi | E29: Delhi | F29: App | G29: Bronze | H29: Running Shoes | I29: Footwear | J29: 5 | K29: 2100 | L29: =J29*K29 -> 10500 | M29: Processing | N29: No
A30: ORD-10030 | B30: 45609 | C30: Amit Joshi | D30: Pune | E30: Maharashtra | F30: Website | G30: Silver | H30: Protein Powder | I30: Health | J30: 3 | K30: 1500 | L30: =J30*K30 -> 4500 | M30: Delivered | N30: No | O30: 5
A31: ORD-10031 | B31: 45622 | C31: Divya Gupta | D31: Pune | E31: Maharashtra | F31: App | G31: Gold | H31: Bluetooth Speaker | I31: Electronics | J31: 5 | K31: 3200 | L31: =J31*K31 -> 16000 | M31: Delivered | N31: No | O31: 3
A32: ORD-10032 | B32: 45551 | C32: Arjun Kumar | D32: Pune | E32: Maharashtra | F32: App | G32: Silver | H32: Smartwatch | I32: Electronics | J32: 3 | K32: 6900 | L32: =J32*K32 -> 20700 | M32: Shipped | N32: No
A33: ORD-10033 | B33: 45652 | C33: Divya Iyer | D33: Mumbai | E33: Maharashtra | F33: WhatsApp | G33: Silver | H33: Face Cream | I33: Beauty | J33: 1 | K33: 800 | L33: =J33*K33 -> 800 | M33: Delivered | N33: No | O33: 3
A34: ORD-10034 | B34: 45575 | C34: Vikram Reddy | D34: Hyderabad | E34: Telangana | F34: WhatsApp | G34: Silver | H34: Notebook Set | I34: Stationery | J34: 3 | K34: 200 | L34: =J34*K34 -> 600 | M34: Cancelled | N34: No
A35: ORD-10035 | B35: 45427 | C35: Nikhil Gupta | D35: Hyderabad | E35: Telangana | F35: App | G35: Gold | H35: Protein Powder | I35: Health | J35: 4 | K35: 1600 | L35: =J35*K35 -> 6400 | M35: Delivered | N35: Yes | O35: 3
A36: ORD-10036 | B36: 45618 | C36: Arjun Kumar | D36: Ahmedabad | E36: Gujarat | F36: WhatsApp | G36: Bronze | H36: Water Bottle | I36: Sports | J36: 5 | K36: 200 | L36: =J36*K36 -> 1000 | M36: Delivered | N36: No | O36: 5
A37: ORD-10037 | B37: 45368 | C37: Kavya Sharma | D37: Pune | E37: Maharashtra | F37: WhatsApp | G37: Bronze | H37: Yoga Mat | I37: Sports | J37: 4 | K37: 600 | L37: =J37*K37 -> 2400 | M37: Delivered | N37: No | O37: 3
A38: ORD-10038 | B38: 45475 | C38: Kiran Singh | D38: Delhi | E38: Delhi | F38: Website | G38: Bronze | H38: Face Cream | I38: Beauty | J38: 4 | K38: 800 | L38: =J38*K38 -> 3200 | M38: Delivered | N38: No | O38: 3
A39: ORD-10039 | B39: 45503 | C39: Rahul Kumar | D39: Pune | E39: Maharashtra | F39: Website | G39: Bronze | H39: Sneakers | I39: Footwear | J39: 2 | K39: 2700 | L39: =J39*K39 -> 5400 | M39: Delivered | N39: No | O39: 3
A40: ORD-10040 | B40: 45487 | C40: Priya Gupta | D40: Chennai | E40: Tamil Nadu | F40: App | G40: Bronze | H40: Smartwatch | I40: Electronics | J40: 3 | K40: 7800 | L40: =J40*K40 -> 23400 | M40: Delivered | N40: Yes | O40: 3
...

Sheet Summary
A1: Sheet UI Builder — Test Dataset
A3: About this file
A5: Total Orders | B5: =COUNTA(Orders!A2:A1000) -> 200
A6: Total Revenue (₹) | B6: =SUM(Orders!L2:L1000) -> 1611500
A7: Avg Order Value (₹) | B7: =AVERAGE(Orders!L2:L1000) -> 8057.5
A8: Unique Customers | B8: =SUMPRODUCT(1/COUNTIF(Orders!C2:C201,Orders!C2:C201)) -> 131
A9: Delivered Orders | B9: =COUNTIF(Orders!M2:M1000,"Delivered") -> 97
A10: Return Rate | B10: =COUNTIF(Orders!N2:N1000,"Yes")/COUNTA(Orders!A2:A1000) -> 0.145
